Workbook
Name SegmentaciónDeDatos_Auditoría: #N/A
Name SegmentaciónDeDatos_Responsable: #N/A
Name SegmentaciónDeDatos_Vigencia: #N/A

Sheet Tablero
G29: Fecha Última actualización | I29: 46183.437

Sheet Calculos 2
A3: Etiquetas de fila | B3: Cuenta de No. Hallazgo | C3: Suma de Total Planes de acción | D3: Suma de Abiertos | E3: Suma de Vencidos | F3: Suma de Finalizados | G3: Suma de Auditoría
A4: 2023 | B4: 19 | C4: 24 | D4: 0 | E4: 0 | F4: 24 | G4: 1672
A5: 2024 | B5: 19 | C5: 26 | D5: 0 | E5: 2 | F5: 24 | G5: 1710
A6: 2025 | B6: 29 | C6: 34 | D6: 11 | E6: 4 | F6: 19 | G6: 2610
A7: Total general | B7: 67 | C7: 84 | D7: 11 | E7: 6 | F7: 67 | G7: 5992
A9: Etiquetas de fila | B9: Suma de Total Planes de acción | C9: Suma de Abiertos | D9: Suma de Vencidos | E9: Suma de Finalizados
A10: DIRECCIÓNDEGESTIÓNFINANCIERA | B10: 15 | C10: 1 | D10: 1 | E10: 13
A11: DIRECCIÓNDEGESTIÓNFINANCIERA/DIRECCIÓNDERECURSOSFÍSICOSYNEGOCIOS | B11: 1 | C11: 1 | D11: 0 | E11: 0
A12: DIRECCIÓNDEGESTIÓNFINANCIERA/SUBGERENCIAJURÍDICA | B12: 1 | C12: 0 | D12: 0 | E12: 1
A13: DIRECCIÓNDEGESTIÓNHUMANA | B13: 10 | C13: 0 | D13: 0 | E13: 10
A14: DIRECCIÓNDEINFRAESTRUCTURA | B14: 2 | C14: 1 | D14: 0 | E14: 1
A15: DIRECCIÓNDERECURSOSFÍSICOS | B15: 2 | C15: 0 | D15: 0 | E15: 2
A16: DIRECCIÓNDERECURSOSFÍSICOSYNEGOCIOS | B16: 4 | C16: 1 | D16: 0 | E16: 3
A17: DIRECCIÓNDERECURSOSFÍSICOSYNEGOCIOS/SUBGERENCIAJURÍDICA | B17: 1 | C17: 1 | D17: 0 | E17: 0
A18: DIRECCIÓNDERECURSOSTECNOLÓGICOS DIRECCIÓNDEGESTIÓNFINANCIERA | B18: 1 | C18: 0 | D18: 0 | E18: 1
A19: DIRECCIÓNDESEGURIDADOPERACIONAL | B19: 1 | C19: 0 | D19: 0 | E19: 1
A20: DIRECCIÓNDESERVICIOALTRANSPORTADOR | B20: 2 | C20: 0 | D20: 0 | E20: 2
A21: DIRECCIÓNDESERVICIOALTRANSPORTADOR/DIRECCIÓNDERECURSOSTECNOLÓGICOS | B21: 1 | C21: 0 | D21: 0 | E21: 1
... A35: Total general | B35: 84 | C35: 11 | D35: 6 | E35: 67

Sheet Hoja5
C3: Tabla 1: Planes de Acción por Auditoría | K3: Tabla 2: Planes de Acción por unico Responsable
C5: Vigencia | D5: PAD | E5: Total Hallazgos | F5: Total Planes de Acción | G5: Abierto en término | H5: Vencido | I5: Finalizado | K5: Área Responsable | L5: Total Planes de Acción | M5: Abierto en término | N5: Vencido | O5: Finalizado
C6: 2023 | D6: 88 | E6: 19 | F6: =+GETPIVOTDATA("Suma de Total Planes de acción",'Calculos 2'!$A$3,"Vigencia",2023) -> 24 | G6: =+GETPIVOTDATA("Suma de Abiertos",'Calculos 2'!$A$3,"Vigencia",2023) -> 0 | H6: =+GETPIVOTDATA("Suma de Vencidos",'Calculos 2'!$A$3,"Vigencia",2023) -> 0 | I6: =+GETPIVOTDATA("Suma de Finalizados",'Calculos 2'!$A$3,"Vigencia",2023) -> 24 | K6: Dirección de Gestión Financiera | L6: =+GETPIVOTDATA("Suma de Total Planes de acción",'Calculos 2'!$A$9,"Responsable ","DIRECCIÓNDEGESTIÓNFINANCIERA") -> 15 | M6: =+GETPIVOTDATA("Suma de Abiertos",'Calculos 2'!$A$9,"Responsable ","DIRECCIÓNDEGESTIÓNFINANCIERA") -> 1 | N6: =+GETPIVOTDATA("Suma de Vencidos",'Calculos 2'!$A$9,"Responsable ","DIRECCIÓNDEGESTIÓNFINANCIERA") -> 1 | O6: =+GETPIVOTDATA("Suma de Finalizados",'Calculos 2'!$A$9,"Responsable ","DIRECCIÓNDEGESTIÓNFINANCIERA") -> 13
C7: 2024 | D7: 90 | E7: 14 | F7: =+GETPIVOTDATA("Suma de Total Planes de acción",'Calculos 2'!$A$3,"Vigencia",2024) -> 26 | G7: =+GETPIVOTDATA("Suma de Abiertos",'Calculos 2'!$A$3,"Vigencia",2024)+GETPIVOTDATA("Suma de Abiertos",'Calculos 2'!$A$3,"Vigencia",2024) -> 0 | H7: =+GETPIVOTDATA("Suma de Vencidos",'Calculos 2'!$A$3,"Vigencia",2024) -> 2 | I7: =+GETPIVOTDATA("Suma de Finalizados",'Calculos 2'!$A$3,"Vigencia",2024) -> 24 | K7: Dirección de Gestión Humana | L7: =+GETPIVOTDATA("Suma de Total Planes de acción",'Calculos 2'!$A$9,"Responsable ","DIRECCIÓNDEGESTIÓNHUMANA") -> 10 | M7: =+GETPIVOTDATA("Suma de Abiertos",'Calculos 2'!$A$9,"Responsable ","DIRECCIÓNDEGESTIÓNHUMANA") -> 0 | N7: =+GETPIVOTDATA("Suma de Vencidos",'Calculos 2'!$A$9,"Responsable ","DIRECCIÓNDEGESTIÓNHUMANA") -> 0 | O7: =+GETPIVOTDATA("Suma de Finalizados",'Calculos 2'!$A$9,"Responsable ","DIRECCIÓNDEGESTIÓNHUMANA") -> 10
C8: 2025 | D8: 90 | E8: 21 | F8: =+GETPIVOTDATA("Suma de Total Planes de acción",'Calculos 2'!$A$3,"Vigencia",2025) -> 34 | G8: =+GETPIVOTDATA("Suma de Abiertos",'Calculos 2'!$A$3,"Vigencia",2025) -> 11 | H8: =+GETPIVOTDATA("Suma de Vencidos",'Calculos 2'!$A$3,"Vigencia",2025) -> 4 | I8: =+GETPIVOTDATA("Suma de Finalizados",'Calculos 2'!$A$3,"Vigencia",2025) -> 19 | K8: Dirección de Infraestructura | L8: =+GETPIVOTDATA("Suma de Total Planes de acción",'Calculos 2'!$A$9,"Responsable ","DIRECCIÓNDEINFRAESTRUCTURA") -> 2 | M8: =+GETPIVOTDATA("Suma de Abiertos",'Calculos 2'!$A$9,"Responsable ","DIRECCIÓNDEINFRAESTRUCTURA") -> 1 | N8: =+GETPIVOTDATA("Suma de Vencidos",'Calculos 2'!$A$9,"Responsable ","DIRECCIÓNDEINFRAESTRUCTURA") -> 0 | O8: =+GETPIVOTDATA("Suma de Finalizados",'Calculos 2'!$A$9,"Responsable ","DIRECCIÓNDEINFRAESTRUCTURA") -> 1
C9: Total General | F9: =SUM(F6:F8) -> 84 | G9: =SUM(G6:G8) -> 11 | H9: =SUM(H6:H8) -> 6 | I9: =SUM(I6:I8) -> 67 | K9: Dirección de Recursos Físicos y Negocios | L9: =+GETPIVOTDATA("Suma de Total Planes de acción",'Calculos 2'!$A$9,"Responsable ","DIRECCIÓNDERECURSOSFÍSICOS")+GETPIVOTDATA("Suma de Total Planes de acción",'Calculos 2'!$A$9,"Responsable ","DIRECCIÓNDERECURSOSFÍSICOSYNEGOCIOS") -> 6 | M9: =+GETPIVOTDATA("Suma de Abiertos",'Calculos 2'!$A$9,"Responsable ","DIRECCIÓNDERECURSOSFÍSICOS")+GETPIVOTDATA("Suma de Abiertos",'Calculos 2'!$A$9,"Responsable ","DIRECCIÓNDERECURSOSFÍSICOSYNEGOCIOS") -> 1 | N9: =+GETPIVOTDATA("Suma de Vencidos",'Calculos 2'!$A$9,"Responsable ","DIRECCIÓNDERECURSOSFÍSICOS")+GETPIVOTDATA("Suma de Vencidos",'Calculos 2'!$A$9,"Responsable ","DIRECCIÓNDERECURSOSFÍSICOSYNEGOCIOS") -> 0 | O9: =+GETPIVOTDATA("Suma de Finalizados",'Calculos 2'!$A$9,"Responsable ","DIRECCIÓNDERECURSOSFÍSICOS")+GETPIVOTDATA("Suma de Finalizados",'Calculos 2'!$A$9,"Responsable ","DIRECCIÓNDERECURSOSFÍSICOSYNEGOCIOS") -> 5
K10: Dirección de Seguridad Operacional | L10: =+GETPIVOTDATA("Suma de Total Planes de acción",'Calculos 2'!$A$9,"Responsable ","DIRECCIÓNDESEGURIDADOPERACIONAL") -> 1 | M10: =+GETPIVOTDATA("Suma de Abiertos",'Calculos 2'!$A$9,"Responsable ","DIRECCIÓNDESEGURIDADOPERACIONAL") -> 0 | N10: =+GETPIVOTDATA("Suma de Vencidos",'Calculos 2'!$A$9,"Responsable ","DIRECCIÓNDESEGURIDADOPERACIONAL") -> 0 | O10: =+GETPIVOTDATA("Suma de Finalizados",'Calculos 2'!$A$9,"Responsable ","DIRECCIÓNDESEGURIDADOPERACIONAL") -> 1
K11: Dirección de Servicio al Transportador | L11: =+GETPIVOTDATA("Suma de Total Planes de acción",'Calculos 2'!$A$9,"Responsable ","DIRECCIÓNDESERVICIOALTRANSPORTADOR") -> 2 | M11: =+GETPIVOTDATA("Suma de Abiertos",'Calculos 2'!$A$9,"Responsable ","DIRECCIÓNDESERVICIOALTRANSPORTADOR") -> 0 | N11: =+GETPIVOTDATA("Suma de Vencidos",'Calculos 2'!$A$9,"Responsable ","DIRECCIÓNDESERVICIOALTRANSPORTADOR") -> 0 | O11: =+GETPIVOTDATA("Suma de Finalizados",'Calculos 2'!$A$9,"Responsable ","DIRECCIÓNDESERVICIOALTRANSPORTADOR") -> 2
K12: Sub Gerencia Corporativa | L12: =+GETPIVOTDATA("Suma de Total Planes de acción",'Calculos 2'!$A$9,"Responsable ","SUBGERENCIACORPORATIVA") -> 3 | M12: =+GETPIVOTDATA("Suma de Abiertos",'Calculos 2'!$A$9,"Responsable ","SUBGERENCIACORPORATIVA") -> 2 | N12: =+GETPIVOTDATA("Suma de Vencidos",'Calculos 2'!$A$9,"Responsable ","SUBGERENCIACORPORATIVA") -> 0 | O12: =+GETPIVOTDATA("Suma de Finalizados",'Calculos 2'!$A$9,"Responsable ","SUBGERENCIACORPORATIVA") -> 1
K13: Sub Gerencia de Planeación y Proyectos | L13: =+GETPIVOTDATA("Suma de Total Planes de acción",'Calculos 2'!$A$9,"Responsable ","SUBGERENCIADEPLANEACIÓNYPROYECTOS")+GETPIVOTDATA("Suma de Total Planes de acción",'Calculos 2'!$A$9,"Responsable ","SUBGERENCIAPLANEACIÓNYPROYECTOS")+GETPIVOTDATA("Suma de Total Planes de acción",'Calculos 2'!$A$9,"Responsable ","SUBGERENCIAPLANEACIÓNYPROYECTOS(ZPP)") -> 17 | M13: =+GETPIVOTDATA("Suma de Abiertos",'Calculos 2'!$A$9,"Responsable ","SUBGERENCIADEPLANEACIÓNYPROYECTOS")+GETPIVOTDATA("Suma de Abiertos",'Calculos 2'!$A$9,"Responsable ","SUBGERENCIAPLANEACIÓNYPROYECTOS")+GETPIVOTDATA("Suma de Abiertos",'Calculos 2'!$A$9,"Responsable ","SUBGERENCIAPLANEACIÓNYPROYECTOS(ZPP)") -> 0 | N13: =+GETPIVOTDATA("Suma de Vencidos",'Calculos 2'!$A$9,"Responsable ","SUBGERENCIADEPLANEACIÓNYPROYECTOS")+GETPIVOTDATA("Suma de Vencidos",'Calculos 2'!$A$9,"Responsable ","SUBGERENCIAPLANEACIÓNYPROYECTOS")+GETPIVOTDATA("Suma de Vencidos",'Calculos 2'!$A$9,"Responsable ","SUBGERENCIAPLANEACIÓNYPROYECTOS(ZPP)") -> 0 | O13: =+GETPIVOTDATA("Suma de Finalizados",'Calculos 2'!$A$9,"Responsable ","SUBGERENCIADEPLANEACIÓNYPROYECTOS")+GETPIVOTDATA("Suma de Finalizados",'Calculos 2'!$A$9,"Responsable ","SUBGERENCIAPLANEACIÓNYPROYECTOS")+GETPIVOTDATA("Suma de Finalizados",'Calculos 2'!$A$9,"Responsable ","SUBGERENCIAPLANEACIÓNYPROYECTOS(ZPP)") -> 17
K14: Sub Gerencia de Servicios Operacionales e Infraestructura | L14: =+GETPIVOTDATA("Suma de Total Planes de acción",'Calculos 2'!$A$9,"Responsable ","SUBGERENCIADESERVICIOSOPERACIONALESEINFRAESTRUCTURA") -> 2 | M14: =+GETPIVOTDATA("Suma de Abiertos",'Calculos 2'!$A$9,"Responsable ","SUBGERENCIADESERVICIOSOPERACIONALESEINFRAESTRUCTURA") -> 1 | N14: =+GETPIVOTDATA("Suma de Vencidos",'Calculos 2'!$A$9,"Responsable ","SUBGERENCIADESERVICIOSOPERACIONALESEINFRAESTRUCTURA") -> 0 | O14: =+GETPIVOTDATA("Suma de Finalizados",'Calculos 2'!$A$9,"Responsable ","SUBGERENCIADESERVICIOSOPERACIONALESEINFRAESTRUCTURA") -> 1
K15: Sub Gerencia Jurídica | L15: =+GETPIVOTDATA("Suma de Total Planes de acción",'Calculos 2'!$A$9,"Responsable ","SUBGERENCIAJURÍDICA") -> 10 | M15: =+GETPIVOTDATA("Suma de Abiertos",'Calculos 2'!$A$9,"Responsable ","SUBGERENCIAJURÍDICA") -> 3 | N15: =+GETPIVOTDATA("Suma de Vencidos",'Calculos 2'!$A$9,"Responsable ","SUBGERENCIAJURÍDICA") -> 0 | O15: =+GETPIVOTDATA("Suma de Finalizados",'Calculos 2'!$A$9,"Responsable ","SUBGERENCIAJURÍDICA") -> 7
K16: Total General | L16: =SUM(L6:L15) -> 68 | M16: =SUM(M6:M15) -> 9 | N16: =SUM(N6:N15) -> 1 | O16: =SUM(O6:O15) -> 58
K18: Tabla 3: Planes de Acción por Responsable Compartido
K20: Área Responsable | L20: Total Planes de Acción | M20: Abierto en término | N20: Vencido | O20: Finalizado
K21: Dirección de Gestión Financiera Dirección de Recursos Físicos y Negocios | L21: =+GETPIVOTDATA("Suma de Total Planes de acción",'Calculos 2'!$A$9,"Responsable ","DIRECCIÓNDEGESTIÓNFINANCIERA/DIRECCIÓNDERECURSOSFÍSICOSYNEGOCIOS") -> 1 | M21: =+GETPIVOTDATA("Suma de Abiertos",'Calculos 2'!$A$9,"Responsable ","DIRECCIÓNDEGESTIÓNFINANCIERA/DIRECCIÓNDERECURSOSFÍSICOSYNEGOCIOS") -> 1 | N21: =+GETPIVOTDATA("Suma de Vencidos",'Calculos 2'!$A$9,"Responsable ","DIRECCIÓNDEGESTIÓNFINANCIERA/DIRECCIÓNDERECURSOSFÍSICOSYNEGOCIOS") -> 0 | O21: =+GETPIVOTDATA("Suma de Finalizados",'Calculos 2'!$A$9,"Responsable ","DIRECCIÓNDEGESTIÓNFINANCIERA/DIRECCIÓNDERECURSOSFÍSICOSYNEGOCIOS") -> 0
K22: Dirección de Gestión Financiera Sub Gerencia Jurídica | L22: =+GETPIVOTDATA("Suma de Total Planes de acción",'Calculos 2'!$A$9,"Responsable ","DIRECCIÓNDEGESTIÓNFINANCIERA/SUBGERENCIAJURÍDICA") -> 1 | M22: =+GETPIVOTDATA("Suma de Abiertos",'Calculos 2'!$A$9,"Responsable ","DIRECCIÓNDEGESTIÓNFINANCIERA/SUBGERENCIAJURÍDICA") -> 0 | N22: =+GETPIVOTDATA("Suma de Vencidos",'Calculos 2'!$A$9,"Responsable ","DIRECCIÓNDEGESTIÓNFINANCIERA/SUBGERENCIAJURÍDICA") -> 0 | O22: =+GETPIVOTDATA("Suma de Finalizados",'Calculos 2'!$A$9,"Responsable ","DIRECCIÓNDEGESTIÓNFINANCIERA/SUBGERENCIAJURÍDICA") -> 1
K23: Dirección de Recursos Físicos y Negocios Sub Gerencia Jurídica | L23: =+GETPIVOTDATA("Suma de Total Planes de acción",'Calculos 2'!$A$9,"Responsable ","DIRECCIÓNDERECURSOSFÍSICOSYNEGOCIOS/SUBGERENCIAJURÍDICA") -> 1 | M23: =+GETPIVOTDATA("Suma de Abiertos",'Calculos 2'!$A$9,"Responsable ","DIRECCIÓNDERECURSOSFÍSICOSYNEGOCIOS/SUBGERENCIAJURÍDICA") -> 1 | N23: =+GETPIVOTDATA("Suma de Vencidos",'Calculos 2'!$A$9,"Responsable ","DIRECCIÓNDERECURSOSFÍSICOSYNEGOCIOS/SUBGERENCIAJURÍDICA") -> 0 | O23: =+GETPIVOTDATA("Suma de Finalizados",'Calculos 2'!$A$9,"Responsable ","DIRECCIÓNDERECURSOSFÍSICOSYNEGOCIOS/SUBGERENCIAJURÍDICA") -> 0
K24: Dirección de Recursos Tecnológicos Dirección de Gestión Financiera | L24: =+GETPIVOTDATA("Suma de Total Planes de acción",'Calculos 2'!$A$9,"Responsable ","DIRECCIÓNDERECURSOSTECNOLÓGICOS DIRECCIÓNDEGESTIÓNFINANCIERA") -> 1 | M24: =+GETPIVOTDATA("Suma de Abiertos",'Calculos 2'!$A$9,"Responsable ","DIRECCIÓNDERECURSOSTECNOLÓGICOS DIRECCIÓNDEGESTIÓNFINANCIERA") -> 0 | N24: =+GETPIVOTDATA("Suma de Vencidos",'Calculos 2'!$A$9,"Responsable ","DIRECCIÓNDERECURSOSTECNOLÓGICOS DIRECCIÓNDEGESTIÓNFINANCIERA") -> 0 | O24: =+GETPIVOTDATA("Suma de Finalizados",'Calculos 2'!$A$9,"Responsable ","DIRECCIÓNDERECURSOSTECNOLÓGICOS DIRECCIÓNDEGESTIÓNFINANCIERA") -> 1
K25: Dirección de Servicio al Transportador Dirección de Recursos Tecnológicos | L25: =+GETPIVOTDATA("Suma de Total Planes de acción",'Calculos 2'!$A$9,"Responsable ","DIRECCIÓNDESERVICIOALTRANSPORTADOR/DIRECCIÓNDERECURSOSTECNOLÓGICOS") -> 1 | M25: =+GETPIVOTDATA("Suma de Abiertos",'Calculos 2'!$A$9,"Responsable ","DIRECCIÓNDESERVICIOALTRANSPORTADOR/DIRECCIÓNDERECURSOSTECNOLÓGICOS") -> 0 | N25: =+GETPIVOTDATA("Suma de Vencidos",'Calculos 2'!$A$9,"Responsable ","DIRECCIÓNDESERVICIOALTRANSPORTADOR/DIRECCIÓNDERECURSOSTECNOLÓGICOS") -> 0 | O25: =+GETPIVOTDATA("Suma de Finalizados",'Calculos 2'!$A$9,"Responsable ","DIRECCIÓNDESERVICIOALTRANSPORTADOR/DIRECCIÓNDERECURSOSTECNOLÓGICOS") -> 1
K26: Oficina de Auditoría Interna Dirección de Gestión Financiera Sub Gerencia Jurídica | L26: =+GETPIVOTDATA("Suma de Total Planes de acción",'Calculos 2'!$A$9,"Responsable ","OFICINADEAUDITORÍAINTERNASUBGERENCIAJURÍDICADIRECCIÓNFINANCIERA") -> 1 | M26: =+GETPIVOTDATA("Suma de Abiertos",'Calculos 2'!$A$9,"Responsable ","OFICINADEAUDITORÍAINTERNASUBGERENCIAJURÍDICADIRECCIÓNFINANCIERA") -> 0 | N26: =+GETPIVOTDATA("Suma de Vencidos",'Calculos 2'!$A$9,"Responsable ","OFICINADEAUDITORÍAINTERNASUBGERENCIAJURÍDICADIRECCIÓNFINANCIERA") -> 0 | O26: =+GETPIVOTDATA("Suma de Finalizados",'Calculos 2'!$A$9,"Responsable ","OFICINADEAUDITORÍAINTERNASUBGERENCIAJURÍDICADIRECCIÓNFINANCIERA") -> 1
K27: Sub Gerencia Corporativa Dirección de Gestión Financiera | L27: =+GETPIVOTDATA("Suma de Total Planes de acción",'Calculos 2'!$A$9,"Responsable ","SUBGERENCIACORPORATIVA/DIRECCIÓNDEGESTIÓNFINANCIERA") -> 3 | M27: =+GETPIVOTDATA("Suma de Abiertos",'Calculos 2'!$A$9,"Responsable ","SUBGERENCIACORPORATIVA/DIRECCIÓNDEGESTIÓNFINANCIERA") -> 0 | N27: =+GETPIVOTDATA("Suma de Vencidos",'Calculos 2'!$A$9,"Responsable ","SUBGERENCIACORPORATIVA/DIRECCIÓNDEGESTIÓNFINANCIERA") -> 3 | O27: =+GETPIVOTDATA("Suma de Finalizados",'Calculos 2'!$A$9,"Responsable ","SUBGERENCIACORPORATIVA/DIRECCIÓNDEGESTIÓNFINANCIERA") -> 0
K28: Sub Gerencia Corporativa Dirección de Recursos Tecnológicos | L28: =+GETPIVOTDATA("Suma de Total Planes de acción",'Calculos 2'!$A$9,"Responsable ","SUBGERENCIACORPORATIVA/DIRECCIÓNDERECURSOSTECNOLÓGICOS") -> 2 | M28: =+GETPIVOTDATA("Suma de Abiertos",'Calculos 2'!$A$9,"Responsable ","SUBGERENCIACORPORATIVA/DIRECCIÓNDERECURSOSTECNOLÓGICOS") -> 0 | N28: =+GETPIVOTDATA("Suma de Vencidos",'Calculos 2'!$A$9,"Responsable ","SUBGERENCIACORPORATIVA/DIRECCIÓNDERECURSOSTECNOLÓGICOS") -> 2 | O28: =+GETPIVOTDATA("Suma de Finalizados",'Calculos 2'!$A$9,"Responsable ","SUBGERENCIACORPORATIVA/DIRECCIÓNDERECURSOSTECNOLÓGICOS") -> 0
K29: Sub Gerencia Corporativa Dirección de Gestión Financiera Dirección de Recursos Tecnológicos | L29: =+GETPIVOTDATA("Suma de Total Planes de acción",'Calculos 2'!$A$9,"Responsable ","SUBGERENCIACORPORATIVADIRECCIÓNDEGESTIÓNFINANCIERADIRECCIÓNDERECURSOSTECNOLÓGICOS") -> 1 | M29: =+GETPIVOTDATA("Suma de Abiertos",'Calculos 2'!$A$9,"Responsable ","SUBGERENCIACORPORATIVADIRECCIÓNDEGESTIÓNFINANCIERADIRECCIÓNDERECURSOSTECNOLÓGICOS") -> 0 | N29: =+GETPIVOTDATA("Suma de Vencidos",'Calculos 2'!$A$9,"Responsable ","SUBGERENCIACORPORATIVADIRECCIÓNDEGESTIÓNFINANCIERADIRECCIÓNDERECURSOSTECNOLÓGICOS") -> 0 | O29: =+GETPIVOTDATA("Suma de Finalizados",'Calculos 2'!$A$9,"Responsable ","SUBGERENCIACORPORATIVADIRECCIÓNDEGESTIÓNFINANCIERADIRECCIÓNDERECURSOSTECNOLÓGICOS") -> 1
K30: Sub Gerencia de Planeación y Proyectos Dirección de Gestión Humana | L30: =+GETPIVOTDATA("Suma de Total Planes de acción",'Calculos 2'!$A$9,"Responsable ","SUBGERENCIADEPLANEACIÓNYPROYECTOSDIRECCIÓNDEGESTIÓNHUMANA") -> 2 | M30: =+GETPIVOTDATA("Suma de Abiertos",'Calculos 2'!$A$9,"Responsable ","SUBGERENCIADEPLANEACIÓNYPROYECTOSDIRECCIÓNDEGESTIÓNHUMANA") -> 0 | N30: =+GETPIVOTDATA("Suma de Vencidos",'Calculos 2'!$A$9,"Responsable ","SUBGERENCIADEPLANEACIÓNYPROYECTOSDIRECCIÓNDEGESTIÓNHUMANA") -> 0 | O30: =+GETPIVOTDATA("Suma de Finalizados",'Calculos 2'!$A$9,"Responsable ","SUBGERENCIADEPLANEACIÓNYPROYECTOSDIRECCIÓNDEGESTIÓNHUMANA") -> 2
K31: Sub Gerencia de Planeación y Proyectos Dirección de Recursos Físicos y Negocios | L31: =+GETPIVOTDATA("Suma de Total Planes de acción",'Calculos 2'!$A$9,"Responsable ","SUBGERENCIADEPLANEACIÓNYPROYECTOSDIRECCIÓNDERECURSOSFÍSICOSYNEGOCIOS") -> 1 | M31: =+GETPIVOTDATA("Suma de Abiertos",'Calculos 2'!$A$9,"Responsable ","SUBGERENCIADEPLANEACIÓNYPROYECTOSDIRECCIÓNDERECURSOSFÍSICOSYNEGOCIOS") -> 0 | N31: =+GETPIVOTDATA("Suma de Vencidos",'Calculos 2'!$A$9,"Responsable ","SUBGERENCIADEPLANEACIÓNYPROYECTOSDIRECCIÓNDERECURSOSFÍSICOSYNEGOCIOS") -> 0 | O31: =+GETPIVOTDATA("Suma de Finalizados",'Calculos 2'!$A$9,"Responsable ","SUBGERENCIADEPLANEACIÓNYPROYECTOSDIRECCIÓNDERECURSOSFÍSICOSYNEGOCIOS") -> 1
K32: Sub Gerencia Jurídica Dirección de Gestión Humana | L32: =+GETPIVOTDATA("Suma de Total Planes de acción",'Calculos 2'!$A$9,"Responsable ","SUBGERENCIAJURÍDICADIRECCIÓNDEGESTIÓNHUMANA") -> 1 | M32: =+GETPIVOTDATA("Suma de Abiertos",'Calculos 2'!$A$9,"Responsable ","SUBGERENCIAJURÍDICADIRECCIÓNDEGESTIÓNHUMANA") -> 0 | N32: =+GETPIVOTDATA("Suma de Vencidos",'Calculos 2'!$A$9,"Responsable ","SUBGERENCIAJURÍDICADIRECCIÓNDEGESTIÓNHUMANA") -> 0 | O32: =+GETPIVOTDATA("Suma de Finalizados",'Calculos 2'!$A$9,"Responsable ","SUBGERENCIAJURÍDICADIRECCIÓNDEGESTIÓNHUMANA") -> 1
K33: Total General | L33: =SUM(L21:L32) -> 16 | M33: =SUM(M21:M32) -> 2 | N33: =SUM(N21:N32) -> 5 | O33: =SUM(O21:O32) -> 9
K36: Tabla 3:El total de Planes de Acción es la suma de laTabla 2: Planes de Acción por Responsable y la Tabla 3: Planes de Acción por Responsable compartido
K38: Total Planes de Acción | L38: Total Planes de Acción | M38: Abierto en término | N38: Vencido | O38: Finalizado | Q38: Sin Definir
L39: =+L16+L33 -> 84 | M39: =+M16+M33 -> 11 | N39: =+N16+N33 -> 6 | O39: =+O16+O33 -> 67

Sheet Detalle
A4: VIGENCIA DE LA AUDITORÍA O VISITA | B4: CODIGO AUDITORÍA SEGÚN PAD DE LA VIGENCIA | C4: No. HALLAZGO | D4: DESCRIPCIÓN HALLAZGO | E4: DESCRIPCIÓN ACCIÓN | F4: AREA RESPONSABLE | G4: FECHA DE TERMINACIÓN | H4: ESTADO | I4: Alerta 10 | J4: Alerta 20 | K4: Alerta 30 | L4: Alerta 5
A5: 2025 | B5: 90 | C5: 3.1.1 | D5: HALLAZGO ADMINISTRATIVO CON PRESUNTA INCIDENCIA DISCIPLINARIA POR INCONSISTENCIAS EN LA ENTREGA DE INFORMACIÓN REQUERIDA POR EL ORGANISMO DE CONTROL | E5: DEFINICIÓN DE LA POLITICA CONTABLE QUE INCLUYA DIFERENCIAS DE CONCEPTO ENTRE UN ACTIVO Y EL MANEJO DE LOS PREDIOS PROPIEDAD DE TTSA | F5: DIRECCIÓNDEGESTIÓNFINANCIERA/DIRECCIÓNDERECURSOSFÍSICOSYNEGOCIOS | G5: 2026-06-30 | H5: Abierta | I5: 0 | J5: 0 | K5: 0 | L5: 0
C6: 3.2.1.1.2 | D6: HALLAZGO ADMINISTRATIVO CON PRESUNTA INCIDENCIA DISCIPLINARIA POR DEFICIENCIAS EN EL COBRO DE LOS CÁNONES DE ARRENDAMIENTO CAUSADOS DURANTE LA EJECUCIÓN DE LOS CONTRATOS DE ARRENDAMIENTO A-027-TQLL-2003; A-024-P.D.-2003; T-S.-2009 CÓDIGO A – L.3 EN Z.T.; Y TT NO. 90 DE 2015. | E6: ACTUALIZACIÓN DEL PROCEDIMIENTO DE GESTIÓN INMOBILIARIA QUE DEFINA LOS CONTROLES PARA EJERCER LAS ACCIONES DE COBRO DE CANONES DE ARRENDAMIENTO, EL PROCESO Y RESPONSABLES DE DECLARATORIA DE SINIESTRO EN LOS CASOS EN LOS QUE SE CUENTE CON GARANTÍAS DE ARRENDAMIENTO, O, LOS REQUISITOS, PROCEDIMIENTO Y RESPONSABLES PARA EL EJERCICIO DE ACCIONES DE COBRO COACTIVO | F6: DIRECCIÓNDERECURSOSFÍSICOSYNEGOCIOS/SUBGERENCIAJURÍDICA | G6: 2026-10-13 | H6: Abierta | I6: 0 | J6: 0 | K6: 0 | L6: 0
C7: 3.2.1.1.3 | D7: HALLAZGO ADMINISTRATIVO CON PRESUNTA INCIDENCIA DISCIPLINARIA POR LA GESTIÓN INEFICIENTE DE LA TERMINAL DE TRANSPORTE S.A. DURANTE DEL PROCESO DE EXPROPIACIÓN ADMINISTRATIVA ADELANTADO POR LA EMPRESA FÉRREA REGIONAL S.A.S. RESPECTO DEL PREDIO DENOMINADO “SANTA HELENA”, IDENTIFICADO CON LA MATRÍCULA INMOBILIARIA 051-191183, ASÍ COMO SU GESTIÓN INOPORTUNA EN LA DEFENSA DE LOS INTERESES DE LA ENTIDAD RESPECTO DEL COBRO DEL IMPUESTO PREDIAL | E7: CREACIÓN DE PROCEDIMIENTO PARA TRÁMITE DE EXPROPIACIONES DE LOS BIENES DE LA TTSA | F7: SUBGERENCIAJURÍDICA | G7: 2026-10-13 | H7: Abierta | I7: 0 | J7: 0 | K7: 0 | L7: 0
E8: GESTIÓN PARA LA MODIFICACIÓN DE LA RESOLUCIÓN NO. 25-75400001616-2025 EXPEDIDA POR EL MUNICIPIO DE SOACHA, CON EL FIN DE QUE SE AJUSTE EL ÁREA DEL PREDIO | F8: DIRECCIÓNDERECURSOSFÍSICOSYNEGOCIOS | G8: 2026-10-13 | H8: Abierta | I8: 0 | J8: 0 | K8: 0 | L8: 0
E9: RELIQUIDACIÓN DE IMPUESTOS CON FUNDAMENTO EN LA REDEFINICIÓN DEL ÁREA DEL PREDIO, CONFORME A LA MODIFICACIÓN DE LA RESOLUCIÓN CITADA | F9: DIRECCIÓNDEGESTIÓNFINANCIERA | G9: 2026-10-13 | H9: Abierta | I9: 0 | J9: 0 | K9: 0 | L9: 0
C10: 3.2.1.5.1 | D10: HALLAZGO ADMINISTRATIVO CON INCIDENCIA FISCAL POR LA SUMA DE CUATRO MIL OCHOCIENTOS NOVENTA Y SEIS MILLONES OCHOCIENTOS VEINTIDÓS MIL OCHOCIENTOS VEINTINUEVE PESOS M/CTE $4.896.822.829 Y PRESUNTA INCIDENCIA DISCIPLINARIA POR FALTA DE GESTIÓN OPORTUNA EN LA PRESENTACIÓN DE LAS DECLARACIONES DEL IMPUESTO PREDIAL UNIFICADO DEL INMUEBLE IDENTIFICADO CON CHIP AAA0077FYUH, VIGENCIAS 2015, 2016, 2017, 2020,2021, 2022 Y 2023 | E10: DECISIÓN DE LA DEMANDA INTERPUESTA EL 12/MARZ/2025 CON RADICADO NO. 25000234100020250038300, EN EL TRIBUNAL ADMINISTRATIVO DE CUNDINAMARCA | F10: SUBGERENCIAJURÍDICA | G10: 2026-10-13 | H10: Abierta | I10: 0 | J10: 0 | K10: 0 | L10: 0
C11: 3.4.2.2.1 | D11: HALLAZGO ADMINISTRATIVO CON INCIDENCIA FISCAL EN CUANTÍA DE SEISCIENTOS CINCO MILLONES QUINIENTOS SETENTA MIL CIENTO NOVENTA Y DOS PESOS M/CTE $605.570.192, Y PRESUNTA INCIDENCIA DISCIPLINARIA, POR EL PAGO INJUSTIFICADO DEL AIU Y PARTE DEL IVA EN EL MARCO DEL CONTRATO TT-034-2024. | E11: ANEXO AL ESTUDIO DE MERCADO DE LOS PROCESOS DE SELECCIÓN PARA LA CONTRATACIÓN DE SERVICIOS DE VIGILANCIA, QUE DETALLE LOS COSTOS E IMPUESTOS GENERADOS POR ÉSTE SERVICIO | F11: SUBGERENCIACORPORATIVA | G11: 2026-10-13 | H11: Abierta | I11: 0 | J11: 0 | K11: 0 | L11: 0 | T11: 10 a 15 de julio
E12: CONCEPTOS TÉCNICOS DE COLOMBIA COMPRA EFICIENTE Y DE LOS ENTES REGULADORES Y/O DE CONTROL SOBRE EL TRATAMIENTO DE AIU | F12: SUBGERENCIACORPORATIVA | G12: 2026-10-13 | H12: Abierta | I12: 0 | J12: 0 | K12: 0 | L12: 0
C13: 3.4.2.3.1 | D13: HALLAZGO ADMINISTRATIVO CON PRESUNTA INCIDENCIA DISCIPLINARIA POR NO APLICAR EL PRINCIPIO DE PLANEACIÓN YA QUE SE EVIDENCIA LA ACTUALIZACIÓN DE PRECIOS SEGÚN LA OFERTA COMERCIAL, PARA EL CONTRATO TT 172 DE 2024 SIN QUE EL MISMO TUVIESE FORMULA DE REAJUSTE. | E13: INCORPORACIÓN CONTRACTUAL DE CLÁUSULA DE ACTUALIZACIÓN DE PRECIOS UNITARIOS POR CAMBIO DE VIGENCIA, EN LOS CONTRATOS QUE APLIQUE | F13: DIRECCIÓNDEINFRAESTRUCTURA | G13: 2026-10-13 | H13: Abierta | I13: 0 | J13: 0 | K13: 0 | L13: 0
C14: 3.4.2.3.2 | D14: HALLAZGO ADMINISTRATIVO, POR EL INCUMPLIMIENTO EN LA OBLIGACIÓN DE LA ENTIDAD DE PUBLICAR INFORMACIÓN CONTRACTUAL EN LA PLATAFORMA SECOP II, PARA LOS CONTRATOS TT 172 Y TT 112 DE 2024. | E14: MEMORANDO DE LINEAMIENTOS EMITIDO POR LA SUB GERENCIA JURÍDICA SOBRE EL PROCEDIMIENTO DE PUBLICACIÓN EN LA PLATAFORMA SECOP, LA DEFINICIÓN DE RESPONSABLES, PLAZOS, PUBLICACIONES OBLIGATORIAS Y OPCIONALES | F14: SUBGERENCIAJURÍDICA | G14: 2026-10-13 | H14: Abierta | I14: 0 | J14: 0 | K14: 0 | L14: 0
C15: 4.2.1 | D15: HALLAZGO ADMINISTRATIVO CON PRESUNTA INCIDENCIA DISCIPLINARIA POR FALTA DE DILIGENCIA Y GESTIÓN OPORTUNA DE LOS REGISTROS “NO PAGOS” EN EL ESTACIONAMIENTO EN VÍA (ZONAS DE PARQUEO PAGO – ZPP) POR PARTE DE LA TERMINAL DE TRANSPORTE S.A. (TTSA). | E15: ACTUALIZACIÓN DEL PROCEDIMIENTO GPE-PRO2 GESTIÓN Y RECUPERACIÓN DE LOS REGISTROS SUSCEPTIBLES DE GESTIÓN DE ZPP QUE INCLUYA EL CONTROL AUTOMÁTICO DE LAS ALERTAS QUE GENERA EL APLICATIVO RESPECTO A LOS USOS DE LOS USUARIOS CUANDO PRESETAN REGISTROS "NO PAGOS" PARA QUE EL PERSONAL EN VÍA REALICE EL COBRO Ó EL USUARIO REALICE EL PAGO DEL MISMO PARA PODER HACER USO DE LAS ZONAS DE PARQUEO PAGO | F15: SUBGERENCIADESERVICIOSOPERACIONALESEINFRAESTRUCTURA | G15: 2026-06-30 | H15: Abierta | I15: 0 | J15: 0 | K15: 0 | L15: 0
A16: Total general

Sheet Vencidos
B2: VIGENCIA | C2: PAD | D2: No. HALLAZGO | E2: DESCRIPCIÓN HALLAZGO | F2: DESCRIPCIÓN ACCIÓN | G2: AREA RESPONSABLE | H2: FECHA DE TERMINACIÓN | I2: ENLACE EVIDENCIAS
B3: 2024 | C3: 90 | D3: 3.2.1.2 | E3: HALLAZGO ADMINISTRATIVA CON PRESUNTA INCIDENCIA DISCIPLINARIA Y FISCAL EN CUANTÍA DE $2.124.470, POR PAGO DE SANCIONES E INTERESES DE MORA ANTE LA SECRETARÍA DISTRITAL DE HACIENDA DURANTE LA VIGENCIA 2023 | F3: SE ESTABLECERAN INTERFACES CON LOS DIFERENTES PROGRAMAS DE MANEJO DE INGRESOS, QUE REDUZCAN PROCESOS MANUALES QUE MINIMICEN LA INTERVENCIÓN HUMANA EN EL REGISTRO DE LA INFORMACIÓN | G3: SUBGERENCIACORPORATIVA/DIRECCIÓNDERECURSOSTECNOLÓGICOS | H3: 2025-06-30 | I3: https://drive.google.com/drive/folders/1rVN9dCAaOu7HPMZfk_8Ipi4TNEITP1m_
B4: 2024 | C4: 90 | D4: 3.2.1.3 | E4: HALLAZGO ADMINISTRATIVA CON PRESUNTA INCIDENCIA DISCIPLINARIA Y FISCAL EN CUANTÍA DE $3.902.504, POR PAGO DE SANCIONES E INTERESES DE MORA ANTE LA DIRECCIÓN DE IMPUESTOS Y ADUANAS NACIONALES – DIAN | F4: SE ESTABLECERÁN INTERFACES CON LOS DIFERENTES PROGRAMAS DE MANEJO DE INGRESOS, QUE REDUZCAN PROCESOS MANUALES QUE MINIMICEN LA INTERVENCIÓN HUMANA EN EL REGISTRO DE LA INFORMACIÓN | G4: SUBGERENCIACORPORATIVA/DIRECCIÓNDERECURSOSTECNOLÓGICOS | H4: 2025-06-30 | I4: https://drive.google.com/drive/folders/1dWHLZvVx3dWrHlfG1qALbAqY-VP21Tsm
B5: 2025 | C5: 90 | D5: 3.3.1.1 | E5: HALLAZGO ADMINISTRATIVO POR EL INCUMPLIMIENTO DE ALGUNAS ACTIVIDADES DEL LINEAMIENTO PRESUPUESTAL ORDENADO EN SU MANUAL DE PRESUPUESTO. CÓDIGO: GAF-MN06 VERSIÓN 7, AGOSTO DE 2018. | F5: ACTUALIZACIÓN DEL MANUAL DEL PRESUPUESTO | G5: SUBGERENCIACORPORATIVA/DIRECCIÓNDEGESTIÓNFINANCIERA | H5: 46142 | I5: https://drive.google.com/drive/u/0/folders/14P1qKtAiC-YzKemPT5X0iBzfxnAFb5ip
B6: 2025 | C6: 90 | D6: 3.3.2.2 | E6: HALLAZGO ADMINISTRATIVO CON PRESUNTA INCIDENCIA DISCIPLINARIA, POR CUANTO LA TERMINAL DE TRANSPORTE, POSEE DOS TIPOS DE REGISTROS DE EXPEDICIÓN DE CDP Y CRP, QUE PRESENTAN INCONSISTENCIAS. | F6: ACTUALIZACIÓN DEL MANUAL DEL PRESUPUESTO | G6: SUBGERENCIACORPORATIVA/DIRECCIÓNDEGESTIÓNFINANCIERA | H6: 2026-04-30 | I6: https://drive.google.com/drive/u/0/folders/1gFWUgRMGQMoMIs5t5-wrGMmiUXXbS50u
B7: 2025 | C7: 90 | D7: 3.3.2.3.1 | E7: HALLAZGO ADMINISTRATIVO POR CUANTO LA TERMINAL PRESENTA SALDOS SIN PAGO EN LAS CXP VIGENCIA 2023 A PAGAR EN ENERO DE 2024 Y 2024 A PAGAR EN ENERO DE 2025, INCUMPLIENDO LO SEÑALADO EN SU PROCEDIMIENTO INTERNO. | F7: ACTUALIZACIÓN DEL MANUAL DEL PRESUPUESTO | G7: SUBGERENCIACORPORATIVA/DIRECCIÓNDEGESTIÓNFINANCIERA | H7: 2026-04-30 | I7: https://drive.google.com/drive/u/0/folders/1S5KdfBLYx-YHAeqUV10IyafbWn3tAV6c
B8: 2025 | C8: 90 | D8: 3.4.2.1.1 | E8: HALLAZGO ADMINISTRATIVO CON INCIDENCIA FISCAL EN CUANTÍA DE $1.482.567.858 Y PRESUNTA INCIDENCIA DISCIPLINARIA TODA VEZ QUE, EN DESARROLLO DEL CONTRATO 99 DE 2019 SUSCRITO ENTRE LA TERMINAL DE TRANSPORTE S.A. Y PROTECH INGENIERÍA S.A.S, SE PRODUJO UNA GESTIÓN FISCAL ANTIECONÓMICA, INEFICAZ, INEFICIENTE, PORQUE EL SISTEMA ADQUIRIDO NO CUMPLE CON EL OBJETO DEL CONTRATO, NO ES FUNCIONAL. | F8: PRESENTACIÓN POR PARTE DE LOS SUPERVISORES DEL CONTRATO, DE INFORME QUE DETALLE Y EXPLIQUE EL FUNCIONAMIENTO DE CADA UNO DE LOS COMPONENTES DE LA SOLUCIÓN, Y EVIDENCIA DE LAS PRUEBAS EFECTUADAS PARA EL RECIBO DE LA MISMA. ADEMÁS, DEL FUNCIONAMIENTO ACTUAL DE LA SOLUCIÓN TECNOLÓGICA Y EL ESTADO DE LAS RECLAMACIONES GESTIONADAS ANTE LA ASEGURADORA | G8: SUBGERENCIADESERVICIOSOPERACIONALESEINFRAESTRUCTURA | H8: 2025-12-31 | I8: https://drive.google.com/drive/u/0/folders/1FtPipptfNQSnRuDzBLHttv5QsFbt4_i4
B9: 2025 | C9: 90 | D9: 3.4.2.3.3 | E9: HALLAZGO ADMINISTRATIVO POR NO APLICAR EL PRINCIPIO DE PLANEACIÓN YA QUE SE EVIDENCIA EL PAGO DE LOS ÍTEMS NO PREVISTOS ANTES DE SER APROBADOS POR EL SUPERVISOR DEL CONTRATO TT 112 DE 2024, EVIDENCIANDO UN INCUMPLIMIENTO EN LAS OBLIGACIONES DE LA ENTIDAD. | F9: CAPACITACIÓN POR PARTE DE LA SUBGERENCIA JURÍDICA, SOBRE LA SUPERVISIÓN DE CONTRATOS, QUE INCLUYA ÍTEMS NO PREVISTOS Y RECONOCIMIENTO PARA EL PAGO | G9: SUBGERENCIAJURÍDICA | H9: 2026-02-28 | I9: https://drive.google.com/drive/u/0/folders/1ur2Auhsr5t-nA4bZISLNcN9eQ8lGYGY-
B10: 2025 | C10: 90 | D10: 3.4.2.4.1 | E10: HALLAZGO ADMINISTRATIVO CON PRESUNTA INCIDENCIA DISCIPLINARIA Y PENAL DEBIDO A QUE DE LOS RECURSOS INICIALMENTE ASIGNADOS AL CONTRATO 135 DE 2023 FUERON DISMINUIDOS EN LA SUMA $9.000.00 MILLONES, SIN LA EXPEDICIÓN DEL CORRESPONDIENTE ACTO ADMINISTRATIVO QUE PERMITIERA LA LIBERACIÓN DE ESTOS RECURSOS, GENERANDO LA DESFINANCIACIÓN DEL MISMO. | F10: ACTUALIZACIÓN DEL MANUAL DE PRESUPUESTO PARA LA VALIDACIÓN DE REQUISITOS PARA LA MODIFICACIÓN DE CDP | G10: DIRECCIÓNDEGESTIÓNFINANCIERA | H10: 2026-04-30 | I10: https://drive.google.com/drive/u/0/folders/16uXFDMuYgvGjkp-JJgwIwXgpK9vORInY
B11: 2025 | C11: 90 | D11: 3.4.2.4.1 | E11: HALLAZGO ADMINISTRATIVO CON PRESUNTA INCIDENCIA DISCIPLINARIA Y PENAL DEBIDO A QUE DE LOS RECURSOS INICIALMENTE ASIGNADOS AL CONTRATO 135 DE 2023 FUERON DISMINUIDOS EN LA SUMA $9.000.00 MILLONES, SIN LA EXPEDICIÓN DEL CORRESPONDIENTE ACTO ADMINISTRATIVO QUE PERMITIERA LA LIBERACIÓN DE ESTOS RECURSOS, GENERANDO LA DESFINANCIACIÓN DEL MISMO. | F11: INFORME DE LA DIRECCIÓN FINANCIERA PARA INDICAR EL MANEJO DE LOS CDP | G11: DIRECCIÓNDEGESTIÓNFINANCIERA | H11: 2026-04-30 | I11: https://drive.google.com/drive/u/0/folders/1qaiBaFOogRrmDOJAIqv0IVPFCZcfZjnf

Sheet Abiertos
B2: VIGENCIA | C2: PAD | D2: No. HALLAZGO | E2: DESCRIPCIÓN HALLAZGO | F2: DESCRIPCIÓN ACCIÓN | G2: AREA RESPONSABLE | H2: FECHA DE TERMINACIÓN | I2: ENLACE EVIDENCIAS
B3: 2025 | C3: 90 | D3: 3.1.1 | E3: HALLAZGO ADMINISTRATIVO CON PRESUNTA INCIDENCIA DISCIPLINARIA POR INCONSISTENCIAS EN LA ENTREGA DE INFORMACIÓN REQUERIDA POR EL ORGANISMO DE CONTROL | F3: DEFINICIÓN DE LA POLITICA CONTABLE QUE INCLUYA DIFERENCIAS DE CONCEPTO ENTRE UN ACTIVO Y EL MANEJO DE LOS PREDIOS PROPIEDAD DE TTSA | G3: DIRECCIÓNDEGESTIÓNFINANCIERA/DIRECCIÓNDERECURSOSFÍSICOSYNEGOCIOS | H3: 2026-06-30 | I3: https://drive.google.com/drive/u/0/folders/1bmZSYTZPlrSq234glXYiTJCO48SccgqJ
B4: 2025 | C4: 90 | D4: 3.2.1.1.2 | E4: HALLAZGO ADMINISTRATIVO CON PRESUNTA INCIDENCIA DISCIPLINARIA POR DEFICIENCIAS EN EL COBRO DE LOS CÁNONES DE ARRENDAMIENTO CAUSADOS DURANTE LA EJECUCIÓN DE LOS CONTRATOS DE ARRENDAMIENTO A-027-TQLL-2003; A-024-P.D.-2003; T-S.-2009 CÓDIGO A – L.3 EN Z.T.; Y TT NO. 90 DE 2015. | F4: ACTUALIZACIÓN DEL PROCEDIMIENTO DE GESTIÓN INMOBILIARIA QUE DEFINA LOS CONTROLES PARA EJERCER LAS ACCIONES DE COBRO DE CANONES DE ARRENDAMIENTO, EL PROCESO Y RESPONSABLES DE DECLARATORIA DE SINIESTRO EN LOS CASOS EN LOS QUE SE CUENTE CON GARANTÍAS DE ARRENDAMIENTO, O, LOS REQUISITOS, PROCEDIMIENTO Y RESPONSABLES PARA EL EJERCICIO DE ACCIONES DE COBRO COACTIVO | G4: DIRECCIÓNDERECURSOSFÍSICOSYNEGOCIOS/SUBGERENCIAJURÍDICA | H4: 2026-10-13 | I4: https://drive.google.com/drive/u/0/folders/1QT49y1L5HwPHxc-EwvXz5gLce7HGc71K
B5: 2025 | C5: 90 | D5: 3.2.1.1.3 | E5: HALLAZGO ADMINISTRATIVO CON PRESUNTA INCIDENCIA DISCIPLINARIA POR LA GESTIÓN INEFICIENTE DE LA TERMINAL DE TRANSPORTE S.A. DURANTE DEL PROCESO DE EXPROPIACIÓN ADMINISTRATIVA ADELANTADO POR LA EMPRESA FÉRREA REGIONAL S.A.S. RESPECTO DEL PREDIO DENOMINADO “SANTA HELENA”, IDENTIFICADO CON LA MATRÍCULA INMOBILIARIA 051-191183, ASÍ COMO SU GESTIÓN INOPORTUNA EN LA DEFENSA DE LOS INTERESES DE LA ENTIDAD RESPECTO DEL COBRO DEL IMPUESTO PREDIAL | F5: CREACIÓN DE PROCEDIMIENTO PARA TRÁMITE DE EXPROPIACIONES DE LOS BIENES DE LA TTSA | G5: SUBGERENCIAJURÍDICA | H5: 2026-10-13 | I5: https://drive.google.com/drive/u/0/folders/1kilX7Bb9sV8Qh-eNoVoUyX1WaRol3HVN
B6: 2025 | C6: 90 | D6: 3.2.1.1.3 | E6: HALLAZGO ADMINISTRATIVO CON PRESUNTA INCIDENCIA DISCIPLINARIA POR LA GESTIÓN INEFICIENTE DE LA TERMINAL DE TRANSPORTE S.A. DURANTE DEL PROCESO DE EXPROPIACIÓN ADMINISTRATIVA ADELANTADO POR LA EMPRESA FÉRREA REGIONAL S.A.S. RESPECTO DEL PREDIO DENOMINADO “SANTA HELENA”, IDENTIFICADO CON LA MATRÍCULA INMOBILIARIA 051-191183, ASÍ COMO SU GESTIÓN INOPORTUNA EN LA DEFENSA DE LOS INTERESES DE LA ENTIDAD RESPECTO DEL COBRO DEL IMPUESTO PREDIAL | F6: GESTIÓN PARA LA MODIFICACIÓN DE LA RESOLUCIÓN NO. 25-75400001616-2025 EXPEDIDA POR EL MUNICIPIO DE SOACHA, CON EL FIN DE QUE SE AJUSTE EL ÁREA DEL PREDIO | G6: DIRECCIÓNDERECURSOSFÍSICOSYNEGOCIOS | H6: 2026-10-13 | I6: https://drive.google.com/drive/u/0/folders/1EubnA9GmEsmbl7UFcOUTjsykCzJiqONA
B7: 2025 | C7: 90 | D7: 3.2.1.1.3 | E7: HALLAZGO ADMINISTRATIVO CON PRESUNTA INCIDENCIA DISCIPLINARIA POR LA GESTIÓN INEFICIENTE DE LA TERMINAL DE TRANSPORTE S.A. DURANTE DEL PROCESO DE EXPROPIACIÓN ADMINISTRATIVA ADELANTADO POR LA EMPRESA FÉRREA REGIONAL S.A.S. RESPECTO DEL PREDIO DENOMINADO “SANTA HELENA”, IDENTIFICADO CON LA MATRÍCULA INMOBILIARIA 051-191183, ASÍ COMO SU GESTIÓN INOPORTUNA EN LA DEFENSA DE LOS INTERESES DE LA ENTIDAD RESPECTO DEL COBRO DEL IMPUESTO PREDIAL | F7: RELIQUIDACIÓN DE IMPUESTOS CON FUNDAMENTO EN LA REDEFINICIÓN DEL ÁREA DEL PREDIO, CONFORME A LA MODIFICACIÓN DE LA RESOLUCIÓN CITADA | G7: DIRECCIÓNDEGESTIÓNFINANCIERA | H7: 2026-10-13 | I7: https://drive.google.com/drive/u/0/folders/1RljHJeJbF-CMMxCEgzMTaJzp2W7ejDiQ
B8: 2025 | C8: 90 | D8: 3.2.1.5.1 | E8: HALLAZGO ADMINISTRATIVO CON INCIDENCIA FISCAL POR LA SUMA DE CUATRO MIL OCHOCIENTOS NOVENTA Y SEIS MILLONES OCHOCIENTOS VEINTIDÓS MIL OCHOCIENTOS VEINTINUEVE PESOS M/CTE $4.896.822.829 Y PRESUNTA INCIDENCIA DISCIPLINARIA POR FALTA DE GESTIÓN OPORTUNA EN LA PRESENTACIÓN DE LAS DECLARACIONES DEL IMPUESTO PREDIAL UNIFICADO DEL INMUEBLE IDENTIFICADO CON CHIP AAA0077FYUH, VIGENCIAS 2015, 2016, 2017, 2020,2021, 2022 Y 2023 | F8: DECISIÓN DE LA DEMANDA INTERPUESTA EL 12/MARZ/2025 CON RADICADO NO. 25000234100020250038300, EN EL TRIBUNAL ADMINISTRATIVO DE CUNDINAMARCA | G8: SUBGERENCIAJURÍDICA | H8: 2026-10-13 | I8: https://drive.google.com/drive/u/0/folders/1IS9BzI07vze98OgBUC7T6wwNdSXGpNkr
B9: 2025 | C9: 90 | D9: 3.4.2.2.1 | E9: HALLAZGO ADMINISTRATIVO CON INCIDENCIA FISCAL EN CUANTÍA DE SEISCIENTOS CINCO MILLONES QUINIENTOS SETENTA MIL CIENTO NOVENTA Y DOS PESOS M/CTE $605.570.192, Y PRESUNTA INCIDENCIA DISCIPLINARIA, POR EL PAGO INJUSTIFICADO DEL AIU Y PARTE DEL IVA EN EL MARCO DEL CONTRATO TT-034-2024. | F9: ANEXO AL ESTUDIO DE MERCADO DE LOS PROCESOS DE SELECCIÓN PARA LA CONTRATACIÓN DE SERVICIOS DE VIGILANCIA, QUE DETALLE LOS COSTOS E IMPUESTOS GENERADOS POR ÉSTE SERVICIO | G9: SUBGERENCIACORPORATIVA | H9: 2026-10-13 | I9: https://drive.google.com/drive/u/0/folders/1QycXzX7KEyRWZIzCiZduAkCCQ4bGJsSg
B10: 2025 | C10: 90 | D10: 3.4.2.2.1 | E10: HALLAZGO ADMINISTRATIVO CON INCIDENCIA FISCAL EN CUANTÍA DE SEISCIENTOS CINCO MILLONES QUINIENTOS SETENTA MIL CIENTO NOVENTA Y DOS PESOS M/CTE $605.570.192, Y PRESUNTA INCIDENCIA DISCIPLINARIA, POR EL PAGO INJUSTIFICADO DEL AIU Y PARTE DEL IVA EN EL MARCO DEL CONTRATO TT-034-2024. | F10: CONCEPTOS TÉCNICOS DE COLOMBIA COMPRA EFICIENTE Y DE LOS ENTES REGULADORES Y/O DE CONTROL SOBRE EL TRATAMIENTO DE AIU | G10: SUBGERENCIACORPORATIVA | H10: 2026-10-13 | I10: https://drive.google.com/drive/u/0/folders/1tuZORUcxjX6PVP3fksW0wknXGprxA46m
B11: 2025 | C11: 90 | D11: 3.4.2.3.1 | E11: HALLAZGO ADMINISTRATIVO CON PRESUNTA INCIDENCIA DISCIPLINARIA POR NO APLICAR EL PRINCIPIO DE PLANEACIÓN YA QUE SE EVIDENCIA LA ACTUALIZACIÓN DE PRECIOS SEGÚN LA OFERTA COMERCIAL, PARA EL CONTRATO TT 172 DE 2024 SIN QUE EL MISMO TUVIESE FORMULA DE REAJUSTE. | F11: INCORPORACIÓN CONTRACTUAL DE CLÁUSULA DE ACTUALIZACIÓN DE PRECIOS UNITARIOS POR CAMBIO DE VIGENCIA, EN LOS CONTRATOS QUE APLIQUE | G11: DIRECCIÓNDEINFRAESTRUCTURA | H11: 2026-10-13 | I11: https://drive.google.com/drive/u/0/folders/1f-eEYBbHrafzNrQi8Fnv29rVPz4-XqL_
B12: 2025 | C12: 90 | D12: 3.4.2.3.2 | E12: HALLAZGO ADMINISTRATIVO, POR EL INCUMPLIMIENTO EN LA OBLIGACIÓN DE LA ENTIDAD DE PUBLICAR INFORMACIÓN CONTRACTUAL EN LA PLATAFORMA SECOP II, PARA LOS CONTRATOS TT 172 Y TT 112 DE 2024. | F12: MEMORANDO DE LINEAMIENTOS EMITIDO POR LA SUB GERENCIA JURÍDICA SOBRE EL PROCEDIMIENTO DE PUBLICACIÓN EN LA PLATAFORMA SECOP, LA DEFINICIÓN DE RESPONSABLES, PLAZOS, PUBLICACIONES OBLIGATORIAS Y OPCIONALES | G12: SUBGERENCIAJURÍDICA | H12: 2026-10-13 | I12: https://drive.google.com/drive/u/0/folders/1dsZmy5um6-qhZPvusn_XKe0f6iNeojJy
B13: 2025 | C13: 90 | D13: 4.2.1 | E13: HALLAZGO ADMINISTRATIVO CON PRESUNTA INCIDENCIA DISCIPLINARIA POR FALTA DE DILIGENCIA Y GESTIÓN OPORTUNA DE LOS REGISTROS “NO PAGOS” EN EL ESTACIONAMIENTO EN VÍA (ZONAS DE PARQUEO PAGO – ZPP) POR PARTE DE LA TERMINAL DE TRANSPORTE S.A. (TTSA). | F13: ACTUALIZACIÓN DEL PROCEDIMIENTO GPE-PRO2 GESTIÓN Y RECUPERACIÓN DE LOS REGISTROS SUSCEPTIBLES DE GESTIÓN DE ZPP QUE INCLUYA EL CONTROL AUTOMÁTICO DE LAS ALERTAS QUE GENERA EL APLICATIVO RESPECTO A LOS USOS DE LOS USUARIOS CUANDO PRESETAN REGISTROS "NO PAGOS" PARA QUE EL PERSONAL EN VÍA REALICE EL COBRO Ó EL USUARIO REALICE EL PAGO DEL MISMO PARA PODER HACER USO DE LAS ZONAS DE PARQUEO PAGO | G13: SUBGERENCIADESERVICIOSOPERACIONALESEINFRAESTRUCTURA | H13: 2026-06-30 | I13: https://drive.google.com/drive/u/0/folders/1ob0EHj5xccHYorw-3njw11UNR-cvSjI2

Sheet Hoja4
B2: VIGENCIA DE LA AUDITORÍA O VISITA | C2: CODIGO AUDITORÍA SEGÚN PAD DE LA VIGENCIA | D2: No. HALLAZGO | E2: DESCRIPCIÓN HALLAZGO | F2: DESCRIPCIÓN ACCIÓN | G2: AREA RESPONSABLE | H2: FECHA DE TERMINACIÓN
B3: 2024 | C3: 90 | D3: 3.2.1.2 | E3: HALLAZGO ADMINISTRATIVA CON PRESUNTA INCIDENCIA DISCIPLINARIA Y FISCAL EN CUANTÍA DE $2.124.470, POR PAGO DE SANCIONES E INTERESES DE MORA ANTE LA SECRETARÍA DISTRITAL DE HACIENDA DURANTE LA VIGENCIA 2023 | F3: SE ESTABLECERAN INTERFACES CON LOS DIFERENTES PROGRAMAS DE MANEJO DE INGRESOS, QUE REDUZCAN PROCESOS MANUALES QUE MINIMICEN LA INTERVENCIÓN HUMANA EN EL REGISTRO DE LA INFORMACIÓN | G3: SUBGERENCIACORPORATIVA/DIRECCIÓNDERECURSOSTECNOLÓGICOS | H3: 2025-06-30
B4: 2024 | C4: 90 | D4: 3.2.1.3 | E4: HALLAZGO ADMINISTRATIVA CON PRESUNTA INCIDENCIA DISCIPLINARIA Y FISCAL EN CUANTÍA DE $3.902.504, POR PAGO DE SANCIONES E INTERESES DE MORA ANTE LA DIRECCIÓN DE IMPUESTOS Y ADUANAS NACIONALES – DIAN | F4: SE ESTABLECERÁN INTERFACES CON LOS DIFERENTES PROGRAMAS DE MANEJO DE INGRESOS, QUE REDUZCAN PROCESOS MANUALES QUE MINIMICEN LA INTERVENCIÓN HUMANA EN EL REGISTRO DE LA INFORMACIÓN | G4: SUBGERENCIACORPORATIVA/DIRECCIÓNDERECURSOSTECNOLÓGICOS | H4: 2025-06-30
B5: 2025 | C5: 90 | D5: 3.3.1.1 | E5: HALLAZGO ADMINISTRATIVO POR EL INCUMPLIMIENTO DE ALGUNAS ACTIVIDADES DEL LINEAMIENTO PRESUPUESTAL ORDENADO EN SU MANUAL DE PRESUPUESTO. CÓDIGO: GAF-MN06 VERSIÓN 7, AGOSTO DE 2018. | F5: ACTUALIZACIÓN DEL MANUAL DEL PRESUPUESTO | G5: SUBGERENCIACORPORATIVA/DIRECCIÓNDEGESTIÓNFINANCIERA | H5: 46142
B6: 2025 | D6: 3.3.2.2 | E6: HALLAZGO ADMINISTRATIVO CON PRESUNTA INCIDENCIA DISCIPLINARIA, POR CUANTO LA TERMINAL DE TRANSPORTE, POSEE DOS TIPOS DE REGISTROS DE EXPEDICIÓN DE CDP Y CRP, QUE PRESENTAN INCONSISTENCIAS. | F6: ACTUALIZACIÓN DEL MANUAL DEL PRESUPUESTO | G6: SUBGERENCIACORPORATIVA/DIRECCIÓNDEGESTIÓNFINANCIERA | H6: 2026-04-30
B7: 2025 | D7: 3.3.2.3.1 | E7: HALLAZGO ADMINISTRATIVO POR CUANTO LA TERMINAL PRESENTA SALDOS SIN PAGO EN LAS CXP VIGENCIA 2023 A PAGAR EN ENERO DE 2024 Y 2024 A PAGAR EN ENERO DE 2025, INCUMPLIENDO LO SEÑALADO EN SU PROCEDIMIENTO INTERNO. | F7: ACTUALIZACIÓN DEL MANUAL DEL PRESUPUESTO | G7: SUBGERENCIACORPORATIVA/DIRECCIÓNDEGESTIÓNFINANCIERA | H7: 2026-04-30
B8: 2025 | D8: 3.4.2.1.1 | E8: HALLAZGO ADMINISTRATIVO CON INCIDENCIA FISCAL EN CUANTÍA DE $1.482.567.858 Y PRESUNTA INCIDENCIA DISCIPLINARIA TODA VEZ QUE, EN DESARROLLO DEL CONTRATO 99 DE 2019 SUSCRITO ENTRE LA TERMINAL DE TRANSPORTE S.A. Y PROTECH INGENIERÍA S.A.S, SE PRODUJO UNA GESTIÓN FISCAL ANTIECONÓMICA, INEFICAZ, INEFICIENTE, PORQUE EL SISTEMA ADQUIRIDO NO CUMPLE CON EL OBJETO DEL CONTRATO, NO ES FUNCIONAL. | F8: PRESENTACIÓN POR PARTE DE LOS SUPERVISORES DEL CONTRATO, DE INFORME QUE DETALLE Y EXPLIQUE EL FUNCIONAMIENTO DE CADA UNO DE LOS COMPONENTES DE LA SOLUCIÓN, Y EVIDENCIA DE LAS PRUEBAS EFECTUADAS PARA EL RECIBO DE LA MISMA. ADEMÁS, DEL FUNCIONAMIENTO ACTUAL DE LA SOLUCIÓN TECNOLÓGICA Y EL ESTADO DE LAS RECLAMACIONES GESTIONADAS ANTE LA ASEGURADORA | G8: SUBGERENCIADESERVICIOSOPERACIONALESEINFRAESTRUCTURA | H8: 2025-12-31
B9: 2025 | D9: 3.4.2.3.3 | E9: HALLAZGO ADMINISTRATIVO POR NO APLICAR EL PRINCIPIO DE PLANEACIÓN YA QUE SE EVIDENCIA EL PAGO DE LOS ÍTEMS NO PREVISTOS ANTES DE SER APROBADOS POR EL SUPERVISOR DEL CONTRATO TT 112 DE 2024, EVIDENCIANDO UN INCUMPLIMIENTO EN LAS OBLIGACIONES DE LA ENTIDAD. | F9: CAPACITACIÓN POR PARTE DE LA SUBGERENCIA JURÍDICA, SOBRE LA SUPERVISIÓN DE CONTRATOS, QUE INCLUYA ÍTEMS NO PREVISTOS Y RECONOCIMIENTO PARA EL PAGO | G9: SUBGERENCIAJURÍDICA | H9: 2026-02-28
B10: 2025 | D10: 3.4.2.4.1 | E10: HALLAZGO ADMINISTRATIVO CON PRESUNTA INCIDENCIA DISCIPLINARIA Y PENAL DEBIDO A QUE DE LOS RECURSOS INICIALMENTE ASIGNADOS AL CONTRATO 135 DE 2023 FUERON DISMINUIDOS EN LA SUMA $9.000.00 MILLONES, SIN LA EXPEDICIÓN DEL CORRESPONDIENTE ACTO ADMINISTRATIVO QUE PERMITIERA LA LIBERACIÓN DE ESTOS RECURSOS, GENERANDO LA DESFINANCIACIÓN DEL MISMO. | F10: ACTUALIZACIÓN DEL MANUAL DE PRESUPUESTO PARA LA VALIDACIÓN DE REQUISITOS PARA LA MODIFICACIÓN DE CDP | G10: DIRECCIÓNDEGESTIÓNFINANCIERA | H10: 2026-04-30
B11: 2025 | D11: 3.4.2.4.1 | F11: INFORME DE LA DIRECCIÓN FINANCIERA PARA INDICAR EL MANEJO DE LOS CDP | G11: DIRECCIÓNDEGESTIÓNFINANCIERA | H11: 2026-04-30

Sheet Resumen
C3: Vigencia | D3: Auditoría | E3: No. Hallazgo | F3: Responsable | G3: Total hallazgos | H3: Total Planes de acción | I3: Abiertos | J3: Vencidos | K3: Finalizados | L3: Alerta 10 | M3: Alerta 20 | N3: Alerta 30 | O3: Alerta 5 | P3: Ene | Q3: Feb | R3: Marzo | S3: Abr | T3: May | U3: Jun
C4: 2025 | D4: 90 | E4: 3.1.1 | F4: DIRECCIÓNDEGESTIÓNFINANCIERA/DIRECCIÓNDERECURSOSFÍSICOSYNEGOCIOS | G4: =IF(COUNTIFS($C$4:C4, C4, $D$4:D4, D4, $E$4:E4, E4)=1, 1, 0) -> 1 | H4: {=SUMPRODUCT((TRIM(CLEAN('Base de Datos'!$F$2:$F$3000))&""=TRIM(CLEAN(C4))&"")*(TRIM(CLEAN('Base de Datos'!$G$2:$G$3000))&""=TRIM(CLEAN(D4))&"")*(TRIM(CLEAN('Base de Datos'!$H$2:$H$3000))&""=TRIM(CLEAN(E4))&"")*(TRIM(CLEAN('Base de Datos'!$U$2:$U$3000))&""=TRIM(CLEAN(F4))&""))} -> 0 | I4: =COUNTIFS('Base de Datos'!$F:$F,$C4,'Base de Datos'!$G:$G,$D4,'Base de Datos'!$H:$H,$E4,'Base de Datos'!$U:$U,$F4,'Base de Datos'!$AA:$AA,"Abierta") -> 0 | J4: =COUNTIFS('Base de Datos'!$F:$F,$C4,'Base de Datos'!$G:$G,$D4,'Base de Datos'!$H:$H,$E4,'Base de Datos'!$U:$U,$F4,'Base de Datos'!$AA:$AA,"Vencida") -> 0 | K4: =COUNTIFS('Base de Datos'!$F:$F,$C4,'Base de Datos'!$G:$G,$D4,'Base de Datos'!$H:$H,$E4,'Base de Datos'!$U:$U,$F4,'Base de Datos'!$AA:$AA,"Finalizada") -> 0 | L4: =COUNTIFS('Base de Datos'!$F:$F,$C4,'Base de Datos'!$G:$G,$D4,'Base de Datos'!$H:$H,$E4,'Base de Datos'!$U:$U,$F4,'Base de Datos'!$AA:$AA,"Abierta",'Base de Datos'!$AC:$AC,"<=10",'Base de Datos'!$AC:$AC,">0") -> 0 | M4: =COUNTIFS('Base de Datos'!$F:$F,$C4,'Base de Datos'!$G:$G,$D4,'Base de Datos'!$H:$H,$E4,'Base de Datos'!$U:$U,$F4,'Base de Datos'!$AA:$AA,"Abierta",'Base de Datos'!$AC:$AC,"<=20",'Base de Datos'!$AC:$AC,">10") -> 0 | N4: =COUNTIFS('Base de Datos'!$F:$F,$C4,'Base de Datos'!$G:$G,$D4,'Base de Datos'!$H:$H,$E4,'Base de Datos'!$U:$U,$F4,'Base de Datos'!$AA:$AA,"Abierta",'Base de Datos'!$AC:$AC,"<=30",'Base de Datos'!$AC:$AC,">20") -> 0 | O4: =COUNTIFS('Base de Datos'!$F:$F,$C4,'Base de Datos'!$G:$G,$D4,'Base de Datos'!$H:$H,$E4,'Base de Datos'!$U:$U,$F4,'Base de Datos'!$AA:$AA,"Abierta",'Base de Datos'!$AG:$AG,1) -> 0 | P4: =COUNTIFS('Base de Datos'!$F:$F, $C4, 'Base de Datos'!$H:$H, $E4, 'Base de Datos'!$U:$U, $F4, 'Base de Datos'!$AA:$AA, "Finalizada", 'Base de Datos'!#REF!, ">=01/01/2026", 'Base de Datos'!#REF!, "<=31/01/2026") -> #REF! | Q4: =COUNTIFS('Base de Datos'!$F:$F, $C4, 'Base de Datos'!$H:$H, $E4, 'Base de Datos'!$U:$U, $F4, 'Base de Datos'!$AA:$AA, "Finalizada", 'Base de Datos'!#REF!, ">=01/02/2026", 'Base de Datos'!#REF!, "<=28/02/2026") -> #REF! | R4: =COUNTIFS('Base de Datos'!$F:$F, $C4, 'Base de Datos'!$H:$H, $E4, 'Base de Datos'!$U:$U, $F4, 'Base de Datos'!$AA:$AA, "Finalizada", 'Base de Datos'!#REF!, ">=01/03/2026", 'Base de Datos'!#REF!, "<=31/03/2026") -> #REF! | S4: =COUNTIFS('Base de Datos'!$F:$F, $C4, 'Base de Datos'!$H:$H, $E4, 'Base de Datos'!$U:$U, $F4, 'Base de Datos'!$AA:$AA, "Finalizada", 'Base de Datos'!#REF!, ">=01/04/2026", 'Base de Datos'!#REF!, "<=30/04/2026") -> #REF! | T4: =COUNTIFS('Base de Datos'!$F:$F, $C4, 'Base de Datos'!$H:$H, $E4, 'Base de Datos'!$U:$U, $F4, 'Base de Datos'!$AA:$AA, "Finalizada", 'Base de Datos'!#REF!, ">=01/05/2026", 'Base de Datos'!#REF!, "<=31/05/2026") -> #REF! | U4: =COUNTIFS('Base de Datos'!$F:$F, $C4, 'Base de Datos'!$H:$H, $E4, 'Base de Datos'!$U:$U, $F4, 'Base de Datos'!$AA:$AA, "Finalizada", 'Base de Datos'!#REF!, ">=01/06/2026", 'Base de Datos'!#REF!, "<=30/06/2026") -> #REF!
C5: 2025 | D5: 90 | E5: 3.1.1 | F5: DIRECCIÓNDEGESTIÓNFINANCIERA | G5: =IF(COUNTIFS($C$4:C5, C5, $D$4:D5, D5, $E$4:E5, E5)=1, 1, 0) -> 0 | H5: {=SUMPRODUCT((TRIM(CLEAN('Base de Datos'!$F$2:$F$3000))&""=TRIM(CLEAN(C5))&"")*(TRIM(CLEAN('Base de Datos'!$G$2:$G$3000))&""=TRIM(CLEAN(D5))&"")*(TRIM(CLEAN('Base de Datos'!$H$2:$H$3000))&""=TRIM(CLEAN(E5))&"")*(TRIM(CLEAN('Base de Datos'!$U$2:$U$3000))&""=TRIM(CLEAN(F5))&""))} -> 0 | I5: =COUNTIFS('Base de Datos'!$F:$F,$C5,'Base de Datos'!$G:$G,$D5,'Base de Datos'!$H:$H,$E5,'Base de Datos'!$U:$U,$F5,'Base de Datos'!$AA:$AA,"Abierta") -> 0 | J5: =COUNTIFS('Base de Datos'!$F:$F,$C5,'Base de Datos'!$G:$G,$D5,'Base de Datos'!$H:$H,$E5,'Base de Datos'!$U:$U,$F5,'Base de Datos'!$AA:$AA,"Vencida") -> 0 | K5: =COUNTIFS('Base de Datos'!$F:$F,$C5,'Base de Datos'!$G:$G,$D5,'Base de Datos'!$H:$H,$E5,'Base de Datos'!$U:$U,$F5,'Base de Datos'!$AA:$AA,"Finalizada") -> 0 | L5: =COUNTIFS('Base de Datos'!$F:$F,$C5,'Base de Datos'!$G:$G,$D5,'Base de Datos'!$H:$H,$E5,'Base de Datos'!$U:$U,$F5,'Base de Datos'!$AA:$AA,"Abierta",'Base de Datos'!$AC:$AC,"<=10",'Base de Datos'!$AC:$AC,">0") -> 0 | M5: =COUNTIFS('Base de Datos'!$F:$F,$C5,'Base de Datos'!$G:$G,$D5,'Base de Datos'!$H:$H,$E5,'Base de Datos'!$U:$U,$F5,'Base de Datos'!$AA:$AA,"Abierta",'Base de Datos'!$AC:$AC,"<=20",'Base de Datos'!$AC:$AC,">10") -> 0 | N5: =COUNTIFS('Base de Datos'!$F:$F,$C5,'Base de Datos'!$G:$G,$D5,'Base de Datos'!$H:$H,$E5,'Base de Datos'!$U:$U,$F5,'Base de Datos'!$AA:$AA,"Abierta",'Base de Datos'!$AC:$AC,"<=30",'Base de Datos'!$AC:$AC,">20") -> 0 | O5: =COUNTIFS('Base de Datos'!$F:$F,$C5,'Base de Datos'!$G:$G,$D5,'Base de Datos'!$H:$H,$E5,'Base de Datos'!$U:$U,$F5,'Base de Datos'!$AA:$AA,"Abierta",'Base de Datos'!$AG:$AG,1) -> 0 | P5: =COUNTIFS('Base de Datos'!$F:$F, $C5, 'Base de Datos'!$H:$H, $E5, 'Base de Datos'!$U:$U, $F5, 'Base de Datos'!$AA:$AA, "Finalizada", 'Base de Datos'!#REF!, ">=01/01/2026", 'Base de Datos'!#REF!, "<=31/01/2026") -> #REF! | Q5: =COUNTIFS('Base de Datos'!$F:$F, $C5, 'Base de Datos'!$H:$H, $E5, 'Base de Datos'!$U:$U, $F5, 'Base de Datos'!$AA:$AA, "Finalizada", 'Base de Datos'!#REF!, ">=01/02/2026", 'Base de Datos'!#REF!, "<=28/02/2026") -> #REF! | R5: =COUNTIFS('Base de Datos'!$F:$F, $C5, 'Base de Datos'!$H:$H, $E5, 'Base de Datos'!$U:$U, $F5, 'Base de Datos'!$AA:$AA, "Finalizada", 'Base de Datos'!#REF!, ">=01/03/2026", 'Base de Datos'!#REF!, "<=31/03/2026") -> #REF! | S5: =COUNTIFS('Base de Datos'!$F:$F, $C5, 'Base de Datos'!$H:$H, $E5, 'Base de Datos'!$U:$U, $F5, 'Base de Datos'!$AA:$AA, "Finalizada", 'Base de Datos'!#REF!, ">=01/04/2026", 'Base de Datos'!#REF!, "<=30/04/2026") -> #REF! | T5: =COUNTIFS('Base de Datos'!$F:$F, $C5, 'Base de Datos'!$H:$H, $E5, 'Base de Datos'!$U:$U, $F5, 'Base de Datos'!$AA:$AA, "Finalizada", 'Base de Datos'!#REF!, ">=01/05/2026", 'Base de Datos'!#REF!, "<=31/05/2026") -> #REF! | U5: =COUNTIFS('Base de Datos'!$F:$F, $C5, 'Base de Datos'!$H:$H, $E5, 'Base de Datos'!$U:$U, $F5, 'Base de Datos'!$AA:$AA, "Finalizada", 'Base de Datos'!#REF!, ">=01/06/2026", 'Base de Datos'!#REF!, "<=30/06/2026") -> #REF!
C6: 2025 | D6: 90 | E6: 3.1.2 | F6: DIRECCIÓNDERECURSOSFÍSICOSYNEGOCIOS | G6: =IF(COUNTIFS($C$4:C6, C6, $D$4:D6, D6, $E$4:E6, E6)=1, 1, 0) -> 1 | H6: {=SUMPRODUCT((TRIM(CLEAN('Base de Datos'!$F$2:$F$3000))&""=TRIM(CLEAN(C6))&"")*(TRIM(CLEAN('Base de Datos'!$G$2:$G$3000))&""=TRIM(CLEAN(D6))&"")*(TRIM(CLEAN('Base de Datos'!$H$2:$H$3000))&""=TRIM(CLEAN(E6))&"")*(TRIM(CLEAN('Base de Datos'!$U$2:$U$3000))&""=TRIM(CLEAN(F6))&""))} -> 0 | I6: =COUNTIFS('Base de Datos'!$F:$F,$C6,'Base de Datos'!$G:$G,$D6,'Base de Datos'!$H:$H,$E6,'Base de Datos'!$U:$U,$F6,'Base de Datos'!$AA:$AA,"Abierta") -> 0 | J6: =COUNTIFS('Base de Datos'!$F:$F,$C6,'Base de Datos'!$G:$G,$D6,'Base de Datos'!$H:$H,$E6,'Base de Datos'!$U:$U,$F6,'Base de Datos'!$AA:$AA,"Vencida") -> 0 | K6: =COUNTIFS('Base de Datos'!$F:$F,$C6,'Base de Datos'!$G:$G,$D6,'Base de Datos'!$H:$H,$E6,'Base de Datos'!$U:$U,$F6,'Base de Datos'!$AA:$AA,"Finalizada") -> 0 | L6: =COUNTIFS('Base de Datos'!$F:$F,$C6,'Base de Datos'!$G:$G,$D6,'Base de Datos'!$H:$H,$E6,'Base de Datos'!$U:$U,$F6,'Base de Datos'!$AA:$AA,"Abierta",'Base de Datos'!$AC:$AC,"<=10",'Base de Datos'!$AC:$AC,">0") -> 0 | M6: =COUNTIFS('Base de Datos'!$F:$F,$C6,'Base de Datos'!$G:$G,$D6,'Base de Datos'!$H:$H,$E6,'Base de Datos'!$U:$U,$F6,'Base de Datos'!$AA:$AA,"Abierta",'Base de Datos'!$AC:$AC,"<=20",'Base de Datos'!$AC:$AC,">10") -> 0 | N6: =COUNTIFS('Base de Datos'!$F:$F,$C6,'Base de Datos'!$G:$G,$D6,'Base de Datos'!$H:$H,$E6,'Base de Datos'!$U:$U,$F6,'Base de Datos'!$AA:$AA,"Abierta",'Base de Datos'!$AC:$AC,"<=30",'Base de Datos'!$AC:$AC,">20") -> 0 | O6: =COUNTIFS('Base de Datos'!$F:$F,$C6,'Base de Datos'!$G:$G,$D6,'Base de Datos'!$H:$H,$E6,'Base de Datos'!$U:$U,$F6,'Base de Datos'!$AA:$AA,"Abierta",'Base de Datos'!$AG:$AG,1) -> 0 | P6: =COUNTIFS('Base de Datos'!$F:$F, $C6, 'Base de Datos'!$H:$H, $E6, 'Base de Datos'!$U:$U, $F6, 'Base de Datos'!$AA:$AA, "Finalizada", 'Base de Datos'!#REF!, ">=01/01/2026", 'Base de Datos'!#REF!, "<=31/01/2026") -> #REF! | Q6: =COUNTIFS('Base de Datos'!$F:$F, $C6, 'Base de Datos'!$H:$H, $E6, 'Base de Datos'!$U:$U, $F6, 'Base de Datos'!$AA:$AA, "Finalizada", 'Base de Datos'!#REF!, ">=01/02/2026", 'Base de Datos'!#REF!, "<=28/02/2026") -> #REF! | R6: =COUNTIFS('Base de Datos'!$F:$F, $C6, 'Base de Datos'!$H:$H, $E6, 'Base de Datos'!$U:$U, $F6, 'Base de Datos'!$AA:$AA, "Finalizada", 'Base de Datos'!#REF!, ">=01/03/2026", 'Base de Datos'!#REF!, "<=31/03/2026") -> #REF! | S6: =COUNTIFS('Base de Datos'!$F:$F, $C6, 'Base de Datos'!$H:$H, $E6, 'Base de Datos'!$U:$U, $F6, 'Base de Datos'!$AA:$AA, "Finalizada", 'Base de Datos'!#REF!, ">=01/04/2026", 'Base de Datos'!#REF!, "<=30/04/2026") -> #REF! | T6: =COUNTIFS('Base de Datos'!$F:$F, $C6, 'Base de Datos'!$H:$H, $E6, 'Base de Datos'!$U:$U, $F6, 'Base de Datos'!$AA:$AA, "Finalizada", 'Base de Datos'!#REF!, ">=01/05/2026", 'Base de Datos'!#REF!, "<=31/05/2026") -> #REF! | U6: =COUNTIFS('Base de Datos'!$F:$F, $C6, 'Base de Datos'!$H:$H, $E6, 'Base de Datos'!$U:$U, $F6, 'Base de Datos'!$AA:$AA, "Finalizada", 'Base de Datos'!#REF!, ">=01/06/2026", 'Base de Datos'!#REF!, "<=30/06/2026") -> #REF!
C7: 2025 | D7: 90 | E7: 3.2.1.1.1 | F7: DIRECCIÓNDEGESTIÓNHUMANA | G7: =IF(COUNTIFS($C$4:C7, C7, $D$4:D7, D7, $E$4:E7, E7)=1, 1, 0) -> 1 | H7: {=SUMPRODUCT((TRIM(CLEAN('Base de Datos'!$F$2:$F$3000))&""=TRIM(CLEAN(C7))&"")*(TRIM(CLEAN('Base de Datos'!$G$2:$G$3000))&""=TRIM(CLEAN(D7))&"")*(TRIM(CLEAN('Base de Datos'!$H$2:$H$3000))&""=TRIM(CLEAN(E7))&"")*(TRIM(CLEAN('Base de Datos'!$U$2:$U$3000))&""=TRIM(CLEAN(F7))&""))} -> 0 | I7: =COUNTIFS('Base de Datos'!$F:$F,$C7,'Base de Datos'!$G:$G,$D7,'Base de Datos'!$H:$H,$E7,'Base de Datos'!$U:$U,$F7,'Base de Datos'!$AA:$AA,"Abierta") -> 0 | J7: =COUNTIFS('Base de Datos'!$F:$F,$C7,'Base de Datos'!$G:$G,$D7,'Base de Datos'!$H:$H,$E7,'Base de Datos'!$U:$U,$F7,'Base de Datos'!$AA:$AA,"Vencida") -> 0 | K7: =COUNTIFS('Base de Datos'!$F:$F,$C7,'Base de Datos'!$G:$G,$D7,'Base de Datos'!$H:$H,$E7,'Base de Datos'!$U:$U,$F7,'Base de Datos'!$AA:$AA,"Finalizada") -> 0 | L7: =COUNTIFS('Base de Datos'!$F:$F,$C7,'Base de Datos'!$G:$G,$D7,'Base de Datos'!$H:$H,$E7,'Base de Datos'!$U:$U,$F7,'Base de Datos'!$AA:$AA,"Abierta",'Base de Datos'!$AC:$AC,"<=10",'Base de Datos'!$AC:$AC,">0") -> 0 | M7: =COUNTIFS('Base de Datos'!$F:$F,$C7,'Base de Datos'!$G:$G,$D7,'Base de Datos'!$H:$H,$E7,'Base de Datos'!$U:$U,$F7,'Base de Datos'!$AA:$AA,"Abierta",'Base de Datos'!$AC:$AC,"<=20",'Base de Datos'!$AC:$AC,">10") -> 0 | N7: =COUNTIFS('Base de Datos'!$F:$F,$C7,'Base de Datos'!$G:$G,$D7,'Base de Datos'!$H:$H,$E7,'Base de Datos'!$U:$U,$F7,'Base de Datos'!$AA:$AA,"Abierta",'Base de Datos'!$AC:$AC,"<=30",'Base de Datos'!$AC:$AC,">20") -> 0 | O7: =COUNTIFS('Base de Datos'!$F:$F,$C7,'Base de Datos'!$G:$G,$D7,'Base de Datos'!$H:$H,$E7,'Base de Datos'!$U:$U,$F7,'Base de Datos'!$AA:$AA,"Abierta",'Base de Datos'!$AG:$AG,1) -> 0 | P7: =COUNTIFS('Base de Datos'!$F:$F, $C7, 'Base de Datos'!$H:$H, $E7, 'Base de Datos'!$U:$U, $F7, 'Base de Datos'!$AA:$AA, "Finalizada", 'Base de Datos'!#REF!, ">=01/01/2026", 'Base de Datos'!#REF!, "<=31/01/2026") -> #REF! | Q7: =COUNTIFS('Base de Datos'!$F:$F, $C7, 'Base de Datos'!$H:$H, $E7, 'Base de Datos'!$U:$U, $F7, 'Base de Datos'!$AA:$AA, "Finalizada", 'Base de Datos'!#REF!, ">=01/02/2026", 'Base de Datos'!#REF!, "<=28/02/2026") -> #REF! | R7: =COUNTIFS('Base de Datos'!$F:$F, $C7, 'Base de Datos'!$H:$H, $E7, 'Base de Datos'!$U:$U, $F7, 'Base de Datos'!$AA:$AA, "Finalizada", 'Base de Datos'!#REF!, ">=01/03/2026", 'Base de Datos'!#REF!, "<=31/03/2026") -> #REF! | S7: =COUNTIFS('Base de Datos'!$F:$F, $C7, 'Base de Datos'!$H:$H, $E7, 'Base de Datos'!$U:$U, $F7, 'Base de Datos'!$AA:$AA, "Finalizada", 'Base de Datos'!#REF!, ">=01/04/2026", 'Base de Datos'!#REF!, "<=30/04/2026") -> #REF! | T7: =COUNTIFS('Base de Datos'!$F:$F, $C7, 'Base de Datos'!$H:$H, $E7, 'Base de Datos'!$U:$U, $F7, 'Base de Datos'!$AA:$AA, "Finalizada", 'Base de Datos'!#REF!, ">=01/05/2026", 'Base de Datos'!#REF!, "<=31/05/2026") -> #REF! | U7: =COUNTIFS('Base de Datos'!$F:$F, $C7, 'Base de Datos'!$H:$H, $E7, 'Base de Datos'!$U:$U, $F7, 'Base de Datos'!$AA:$AA, "Finalizada", 'Base de Datos'!#REF!, ">=01/06/2026", 'Base de Datos'!#REF!, "<=30/06/2026") -> #REF!
C8: 2025 | D8: 90 | E8: 3.2.1.1.2 | F8: DIRECCIÓNDERECURSOSFÍSICOSYNEGOCIOS/SUBGERENCIAJURÍDICA | G8: =IF(COUNTIFS($C$4:C8, C8, $D$4:D8, D8, $E$4:E8, E8)=1, 1, 0) -> 1 | H8: {=SUMPRODUCT((TRIM(CLEAN('Base de Datos'!$F$2:$F$3000))&""=TRIM(CLEAN(C8))&"")*(TRIM(CLEAN('Base de Datos'!$G$2:$G$3000))&""=TRIM(CLEAN(D8))&"")*(TRIM(CLEAN('Base de Datos'!$H$2:$H$3000))&""=TRIM(CLEAN(E8))&"")*(TRIM(CLEAN('Base de Datos'!$U$2:$U$3000))&""=TRIM(CLEAN(F8))&""))} -> 0 | I8: =COUNTIFS('Base de Datos'!$F:$F,$C8,'Base de Datos'!$G:$G,$D8,'Base de Datos'!$H:$H,$E8,'Base de Datos'!$U:$U,$F8,'Base de Datos'!$AA:$AA,"Abierta") -> 0 | J8: =COUNTIFS('Base de Datos'!$F:$F,$C8,'Base de Datos'!$G:$G,$D8,'Base de Datos'!$H:$H,$E8,'Base de Datos'!$U:$U,$F8,'Base de Datos'!$AA:$AA,"Vencida") -> 0 | K8: =COUNTIFS('Base de Datos'!$F:$F,$C8,'Base de Datos'!$G:$G,$D8,'Base de Datos'!$H:$H,$E8,'Base de Datos'!$U:$U,$F8,'Base de Datos'!$AA:$AA,"Finalizada") -> 0 | L8: =COUNTIFS('Base de Datos'!$F:$F,$C8,'Base de Datos'!$G:$G,$D8,'Base de Datos'!$H:$H,$E8,'Base de Datos'!$U:$U,$F8,'Base de Datos'!$AA:$AA,"Abierta",'Base de Datos'!$AC:$AC,"<=10",'Base de Datos'!$AC:$AC,">0") -> 0 | M8: =COUNTIFS('Base de Datos'!$F:$F,$C8,'Base de Datos'!$G:$G,$D8,'Base de Datos'!$H:$H,$E8,'Base de Datos'!$U:$U,$F8,'Base de Datos'!$AA:$AA,"Abierta",'Base de Datos'!$AC:$AC,"<=20",'Base de Datos'!$AC:$AC,">10") -> 0 | N8: =COUNTIFS('Base de Datos'!$F:$F,$C8,'Base de Datos'!$G:$G,$D8,'Base de Datos'!$H:$H,$E8,'Base de Datos'!$U:$U,$F8,'Base de Datos'!$AA:$AA,"Abierta",'Base de Datos'!$AC:$AC,"<=30",'Base de Datos'!$AC:$AC,">20") -> 0 | O8: =COUNTIFS('Base de Datos'!$F:$F,$C8,'Base de Datos'!$G:$G,$D8,'Base de Datos'!$H:$H,$E8,'Base de Datos'!$U:$U,$F8,'Base de Datos'!$AA:$AA,"Abierta",'Base de Datos'!$AG:$AG,1) -> 0 | P8: =COUNTIFS('Base de Datos'!$F:$F, $C8, 'Base de Datos'!$H:$H, $E8, 'Base de Datos'!$U:$U, $F8, 'Base de Datos'!$AA:$AA, "Finalizada", 'Base de Datos'!#REF!, ">=01/01/2026", 'Base de Datos'!#REF!, "<=31/01/2026") -> #REF! | Q8: =COUNTIFS('Base de Datos'!$F:$F, $C8, 'Base de Datos'!$H:$H, $E8, 'Base de Datos'!$U:$U, $F8, 'Base de Datos'!$AA:$AA, "Finalizada", 'Base de Datos'!#REF!, ">=01/02/2026", 'Base de Datos'!#REF!, "<=28/02/2026") -> #REF! | R8: =COUNTIFS('Base de Datos'!$F:$F, $C8, 'Base de Datos'!$H:$H, $E8, 'Base de Datos'!$U:$U, $F8, 'Base de Datos'!$AA:$AA, "Finalizada", 'Base de Datos'!#REF!, ">=01/03/2026", 'Base de Datos'!#REF!, "<=31/03/2026") -> #REF! | S8: =COUNTIFS('Base de Datos'!$F:$F, $C8, 'Base de Datos'!$H:$H, $E8, 'Base de Datos'!$U:$U, $F8, 'Base de Datos'!$AA:$AA, "Finalizada", 'Base de Datos'!#REF!, ">=01/04/2026", 'Base de Datos'!#REF!, "<=30/04/2026") -> #REF! | T8: =COUNTIFS('Base de Datos'!$F:$F, $C8, 'Base de Datos'!$H:$H, $E8, 'Base de Datos'!$U:$U, $F8, 'Base de Datos'!$AA:$AA, "Finalizada", 'Base de Datos'!#REF!, ">=01/05/2026", 'Base de Datos'!#REF!, "<=31/05/2026") -> #REF! | U8: =COUNTIFS('Base de Datos'!$F:$F, $C8, 'Base de Datos'!$H:$H, $E8, 'Base de Datos'!$U:$U, $F8, 'Base de Datos'!$AA:$AA, "Finalizada", 'Base de Datos'!#REF!, ">=01/06/2026", 'Base de Datos'!#REF!, "<=30/06/2026") -> #REF!
